<mujoco model="ranger_mini_v2">
  <compiler angle="radian"/>

  <option integrator="implicit"/>

  <asset>
    <mesh name="ranger_base" file="assets/ranger-base-link.stl"/>
    <mesh name="ranger_wheel_fl" file="assets/ranger-wheel-1.stl"/>
    <mesh name="ranger_wheel_fr" file="assets/ranger-wheel-2.stl"/>
    <mesh name="ranger_wheel_rl" file="assets/ranger-wheel-3.stl"/>
    <mesh name="ranger_wheel_rr" file="assets/ranger-wheel-4.stl"/>
    <mesh name="ranger_suspension_link_1" file="assets/ranger-suspension-link-1.stl"/>
    <mesh name="ranger_suspension_link_2" file="assets/ranger-suspension-link-2.stl"/>
    <mesh name="ranger_suspension_link_3" file="assets/ranger-suspension-link-3.stl"/>
    <mesh name="ranger_suspension_link_4" file="assets/ranger-suspension-link-4.stl"/>

    <material name="mat_wheel_visual" rgba="0.2 0.2 0.2 1"/>
    <material name="mat_wheel_collider" rgba="1 1 1 0.1"/>

    <material name="mat_arm_white" rgba="1 1 1 1"/>
    <material name="mat_arm_gray" rgba="0.753 0.753 0.753 1"/>

    <mesh name="xarm7_link_base" file="assets/xarm7-link-base.stl"/>
    <mesh name="xarm7_link1" file="assets/xarm7-link1.stl"/>
    <mesh name="xarm7_link2" file="assets/xarm7-link2.stl"/>
    <mesh name="xarm7_link3" file="assets/xarm7-link3.stl"/>
    <mesh name="xarm7_link4" file="assets/xarm7-link4.stl"/>
    <mesh name="xarm7_link5" file="assets/xarm7-link5.stl"/>
    <mesh name="xarm7_link6" file="assets/xarm7-link6.stl"/>
    <mesh name="xarm7_link7" file="assets/xarm7-link7.stl"/>
    <mesh name="xarm7_end_tool" file="assets/xarm7-end-tool.stl"/>
  </asset>

  <default>
    <default class="xarm7">
      <geom type="mesh" material="mat_arm_white"/>
      <joint axis="0 0 1" range="-6.28319 6.28319" frictionloss="1"/>
      <general biastype="affine" ctrlrange="-6.28319 6.28319"/>
      <default class="size1">
        <joint damping="10"/>
        <general gainprm="1500" biasprm="0 -1500 -150" forcerange="-50 50"/>
      </default>
      <default class="size2">
        <joint damping="5"/>
        <general gainprm="1000" biasprm="0 -1000 -100" forcerange="-30 30"/>
      </default>
      <default class="size3">
        <joint damping="2"/>
        <general gainprm="800" biasprm="0 -800 -80" forcerange="-20 20"/>
      </default>
      <site size="0.001" rgba="1 0 0 1" group="4"/>
    </default>
  </default>

  <worldbody>
    <body name="base_link" pos="0 0 0.75">
      <freejoint/>
      <inertial pos="0.000 -0.02 0.00" quat="0.492347 0.507724 -0.508707 0.490946" mass="100" diaginertia="2.54702 1.91073 1.14066" />
      <geom name="base_link_collider" type="box" size="0.25 0.369 0.06" pos="0 0 0.18" rgba="1 1 1 0.1"/>
      <geom name="base_link_visual" type="mesh" contype="0" conaffinity="0" rgba="1 1 1 1" mesh="ranger_base"/>
      <!-- Forward left steering -->
      <body name="fl_steering_wheel_link" pos="-0.182 0.248088 0.116139" quat="0.99999 -0.00436331 0 0">
        <inertial pos="0.0562358 0.0136672 -0.0689303" quat="0.480602 -0.109201 -0.000258328 0.870113" mass="0.258645" diaginertia="0.000990911 0.000881135 0.000289082" />
        <joint name="fl_steering_wheel_joint" pos="0 0 0" axis="0 0 1" range="-2.1 2.1" actuatorfrcrange="-5 5"/>
        <geom name="fl_steering_wheel_visual" type="mesh" contype="0" conaffinity="0" rgba="1 1 1 1" mesh="ranger_suspension_link_1"/>
        <!-- Forward-left wheel -->
        <body name="fl_wheel_link" pos="-0.0208 0.00194295 -0.129803" quat="0.99999 0.00436331 0 0">
          <inertial pos="0.0204393 3.33773e-08 1.33779e-07" quat="0.939607 -0.342254 1.613e-06 -5.8754e-07" mass="1.15818" diaginertia="0.00501965 0.00272122 0.00272119" />
          <joint name="fl_wheel_joint" axis="-1 0 0" damping="1"/>
          <geom name="fl_wheel_visual" type="mesh" contype="0" conaffinity="0" mesh="ranger_wheel_fl" material="mat_wheel_visual"/>
          <geom name="fl_wheel_collider" type="cylinder" size="0.0935 0.026" pos="0.0185 0 0" quat="0.707107 0 0.707107 0" material="mat_wheel_collider"/>
        </body>
      </body>
      <!-- Forward right steering -->
      <body name="fr_steering_wheel_link" pos="0.182 0.248088 0.116139" quat="0.99999 -0.00436331 0 0">
        <inertial pos="-0.0563063 -0.0136807 -0.0689934" quat="0.434721 0.121652 -0.0192069 0.892104" mass="0.258387" diaginertia="0.00100741 0.000933733 0.000328543" />
        <joint name="fr_steering_wheel_joint" pos="0 0 0" axis="0 0 1" range="-2.1 2.1" actuatorfrcrange="-5 5"/>
        <geom name="fr_steering_wheel_visual" type="mesh" contype="0" conaffinity="0" rgba="1 1 1 1" mesh="ranger_suspension_link_2"/>
        <!-- Forward-right wheel -->
        <body name="fr_wheel_link" pos="0.0208 -0.00194295 -0.129803" quat="0.99999 0.00436331 0 0">
          <inertial pos="-0.020454 -1.09626e-07 6.94701e-08" quat="0.969649 0.244501 -1.61246e-06 -4.06588e-07" mass="1.15757" diaginertia="0.00501676 0.0027194 0.00271938" />
          <joint name="fr_wheel_joint" axis="-1 0 0" damping="1"/>
          <geom name="fr_wheel_visual" type="mesh" contype="0" conaffinity="0" mesh="ranger_wheel_fr" material="mat_wheel_visual"/>
          <geom name="fr_wheel_collider" type="cylinder" size="0.0935 0.026" pos="-0.0185 0 0" quat="0.707107 0 0.707107 0" material="mat_wheel_collider"/>
        </body>
      </body>
      <!-- Rear left steering -->
      <body name="rl_steering_wheel_link" pos="-0.182 -0.245893 0.12045" quat="0.99999 -0.00436331 0 0">
        <inertial pos="0.0562358 0.0136672 -0.0689303" quat="0.480602 -0.109201 -0.000258328 0.870113" mass="0.258645" diaginertia="0.000990911 0.000881135 0.000289082" />
        <joint name="rl_steering_wheel_joint" pos="0 0 0" axis="0 0 1" range="-2.1 2.1" actuatorfrcrange="-5 5"/>
        <geom name="rl_steering_wheel_visual" type="mesh" contype="0" conaffinity="0" rgba="1 1 1 1" mesh="ranger_suspension_link_3"/>
        <!-- Rear-left wheel -->
        <body name="rl_wheel_link" pos="-0.0208 0.00194295 -0.129803" quat="0.99999 0.00436331 0 0">
          <inertial pos="0.0204393 3.33773e-08 1.33779e-07" quat="0.939607 -0.342254 1.613e-06 -5.8754e-07" mass="1.15818" diaginertia="0.00501965 0.00272122 0.00272119" />
          <joint name="rl_wheel_joint" axis="-1 0 0" damping="1"/>
          <geom name="rl_wheel_visual" type="mesh" contype="0" conaffinity="0" mesh="ranger_wheel_rl" material="mat_wheel_visual"/>
          <geom name="rl_wheel_collider" type="cylinder" size="0.0935 0.026" pos="0.0185 0 0" quat="0.707107 0 0.707107 0" material="mat_wheel_collider"/>
        </body>
      </body>
      <!-- Rear right steering -->
      <body name="rr_steering_wheel_link" pos="0.182 -0.245893 0.12045" quat="0.99999 -0.00436331 0 0">
        <inertial pos="-0.0562389 0.0136676 -0.0689297" quat="0.870112 0.000253454 0.109184 0.480608" mass="0.25865" diaginertia="0.000990936 0.000881147 0.000289094" />
        <joint name="rr_steering_wheel_joint" pos="0 0 0" axis="0 0 1" range="-2.1 2.1" actuatorfrcrange="-5 5"/>
        <geom name="rr_steering_wheel_visual" type="mesh" contype="0" conaffinity="0" rgba="1 1 1 1" mesh="ranger_suspension_link_4"/>
        <!-- Rear-right wheel -->
        <body name="rr_wheel_link" pos="0.0208 0.00194295 -0.129803" quat="0.99999 0.00436331 0 0">
          <inertial pos="-0.020454 -1.01629e-07 -8.15539e-08" quat="0.647155 0.762358 -5.50799e-07 -1.71001e-06" mass="1.15757" diaginertia="0.00501676 0.0027194 0.00271938" />
          <joint name="rr_wheel_joint" axis="-1 0 0" damping="1"/>
          <geom name="rr_wheel_visual" type="mesh" contype="0" conaffinity="0" mesh="ranger_wheel_rr" material="mat_wheel_visual"/>
          <geom name="rr_wheel_collider" type="cylinder" size="0.0935 0.026" pos="-0.0185 0 0" quat="0.707107 0 0.707107 0" material="mat_wheel_collider"/>
        </body>
      </body>
      <!-- xARM7 -->
      <body name="link_base" pos="0 0 .23" childclass="xarm7">
        <inertial pos="-0.021131 -0.0016302 0.056488" quat="0.696843 0.20176 0.10388 0.680376" mass="0.88556" diaginertia="0.00382023 0.00335282 0.00167725"/>
        <geom mesh="xarm7_link_base"/>
        <body name="link1" pos="0 0 0.267">
          <inertial pos="-0.0002 0.02905 -0.01233" quat="0.978953 -0.202769 -0.00441617 -0.0227264" mass="2.382" diaginertia="0.00569127 0.00533384 0.00293865"/>
          <joint name="joint1" class="size1"/>
          <geom mesh="xarm7_link1"/>
          <body name="link2" quat="1 -1 0 0">
            <inertial pos="0.00022 -0.12856 0.01735" quat="0.50198 0.86483 -0.00778841 0.00483285" mass="1.869" diaginertia="0.00959898 0.00937717 0.00201315"/>
            <joint name="joint2" range="-2.059 2.0944" class="size1"/>
            <geom mesh="xarm7_link2"/>
            <body name="link3" pos="0 -0.293 0" quat="1 1 0 0">
              <inertial pos="0.0466 -0.02463 -0.00768" quat="0.913819 0.289775 0.281481 -0.0416455" mass="1.6383" diaginertia="0.00351721 0.00294089 0.00195868"/>
              <joint name="joint3" class="size2"/>
              <geom mesh="xarm7_link3"/>
              <body name="link4" pos="0.0525 0 0" quat="1 1 0 0">
                <inertial pos="0.07047 -0.11575 0.012" quat="0.422108 0.852026 -0.126025 0.282832" mass="1.7269" diaginertia="0.00657137 0.00647948 0.00186763"/>
                <joint name="joint4" range="-0.19198 3.927" class="size2"/>
                <geom mesh="xarm7_link4"/>
                <body name="link5" pos="0.0775 -0.3425 0" quat="1 1 0 0">
                  <inertial pos="-0.00032 0.01604 -0.026" quat="0.999311 -0.0304457 0.000577067 0.0212082" mass="1.3203" diaginertia="0.00534729 0.00499076 0.0013489"/>
                  <joint name="joint5" class="size2"/>
                  <geom mesh="xarm7_link5"/>
                  <body name="link6" quat="1 1 0 0">
                    <inertial pos="0.06469 0.03278 0.02141" quat="-0.217672 0.772419 0.16258 0.574069" mass="1.325" diaginertia="0.00245421 0.00221646 0.00107273"/>
                    <joint name="joint6" range="-1.69297 3.14159" class="size3"/>
                    <geom mesh="xarm7_link6"/>
                    <body name="link7" pos="0.076 0.097 0" quat="1 -1 0 0">
                      <inertial pos="0 -0.00677 -0.01098" quat="0.487612 0.512088 -0.512088 0.487612" mass="0.17" diaginertia="0.000132176 9.3e-05 5.85236e-05"/>
                      <joint name="joint7" class="size3"/>
                      <geom material="mat_arm_gray" mesh="xarm7_end_tool"/>
                    </body>
                  </body>
                </body>
              </body>
            </body>
          </body>
        </body>
      </body>
    </body>
  </worldbody>

  <contact>
    <exclude body1="base_link" body2="fl_steering_wheel_link"/>
    <exclude body1="base_link" body2="fl_wheel_link"/>
    <exclude body1="fl_steering_wheel_link" body2="fl_wheel_link"/>

    <exclude body1="base_link" body2="fr_steering_wheel_link"/>
    <exclude body1="base_link" body2="fr_wheel_link"/>
    <exclude body1="fr_steering_wheel_link" body2="fr_wheel_link"/>

    <exclude body1="base_link" body2="rl_steering_wheel_link"/>
    <exclude body1="base_link" body2="rl_wheel_link"/>
    <exclude body1="rl_steering_wheel_link" body2="rl_wheel_link"/>

    <exclude body1="base_link" body2="rr_steering_wheel_link"/>
    <exclude body1="base_link" body2="rr_wheel_link"/>
    <exclude body1="rr_steering_wheel_link" body2="rr_wheel_link"/>

    <exclude body1="link_base" body2="base_link"/>
  </contact>

  <actuator>
    <!-- ranger actuators -->
    <motor name="fl_wheel_motor" joint="fl_wheel_joint" ctrlrange="-5 5" ctrllimited="true"/>
    <motor name="fr_wheel_motor" joint="fr_wheel_joint" ctrlrange="-5 5" ctrllimited="true"/>
    <motor name="rl_wheel_motor" joint="rl_wheel_joint" ctrlrange="-5 5" ctrllimited="true"/>
    <motor name="rr_wheel_motor" joint="rr_wheel_joint" ctrlrange="-5 5" ctrllimited="true"/>

    <position name="fl_wheel_steer" joint="fl_steering_wheel_joint" kp="10" kv="1"/>
    <position name="fr_wheel_steer" joint="fr_steering_wheel_joint" kp="10" kv="1"/>
    <position name="rl_wheel_steer" joint="rl_steering_wheel_joint" kp="10" kv="1"/>
    <position name="rr_wheel_steer" joint="rr_steering_wheel_joint" kp="10" kv="1"/>
    <!-- xARM7 -->
    <general name="act1" joint="joint1" class="size1"/>
    <general name="act2" joint="joint2" class="size1" ctrlrange="-2.059 2.0944"/>
    <general name="act3" joint="joint3" class="size2"/>
    <general name="act4" joint="joint4" class="size2" ctrlrange="-0.19198 3.927"/>
    <general name="act5" joint="joint5" class="size2"/>
    <general name="act6" joint="joint6" class="size3" ctrlrange="-1.69297 3.14159"/>
    <general name="act7" joint="joint7" class="size3"/>
  </actuator>
</mujoco>
